{"name": "test_answer", "status": "failed", "statusDetails": {"message": "AssertionError: assert 4 == 5\n +  where 4 = func(3)", "trace": "def test_answer():\n>       assert func(3) == 5\nE       assert 4 == 5\nE        +  where 4 = func(3)\n\ntest_test01.py:27: AssertionError"}, "start": 1500486073808, "stop": 1500486073811, "uuid": "d50ea30c-90d8-44df-a9bc-455ddc961cf9", "historyId": "e53c4247c70ed4fa362a9fa1459ef6a1", "fullName": "TestCases/test_test01#test_answer", "labels": [{"name": "package", "value": "TestCases/test_test01"}]}